Workbook

Sheet Sheet1
A1: DS1-A,D | B1: Chinatown | C1: L72 | I1: L92 | O1: L100 | U1: No Simp
A2: Instance | B2: Answers | C2: A1 | D2: A2 | E2: A3 | F2: A4 | G2: A5 | H2: A6 | I2: B1 | J2: B2 | K2: B3 | L2: B4 | M2: B5 | N2: B6 | O2: C1 | P2: C2 | Q2: C3 | R2: C4 | S2: C5 | T2: C6 | U2: D1 | V2: D2 | W2: D3 | X2: D4 | Y2: D5 | Z2: D6
A3: 1 | B3: b | C3: b | D3: b | E3: b | F3: b | G3: b | I3: b | J3: b | K3: b | L3: b | O3: r | P3: r | Q3: b | R3: b | T3: b | U3: r | V3: b | W3: b | X3: b | Y3: b
A4: 2 | B4: r | C4: b | D4: r | E4: b | F4: b | G4: b | I4: r | J4: b | K4: b | L4: r | O4: r | P4: b | Q4: r | R4: r | T4: r | U4: b | V4: r | W4: b | X4: r | Y4: r
A5: 3 | B5: r | C5: r | D5: r | E5: r | F5: r | G5: r | I5: r | J5: r | K5: r | L5: r | O5: r | P5: b | Q5: r | R5: r | T5: r | U5: r | V5: b | W5: b | X5: b | Y5: r
A6: 4 | B6: b | C6: b | D6: b | E6: b | F6: b | G6: b | I6: b | J6: b | K6: b | L6: r | O6: b | P6: b | Q6: b | R6: b | T6: b | U6: b | V6: b | W6: b | X6: b | Y6: b
A7: 5 | B7: b | C7: b | E7: r | F7: r | G7: b | I7: b | J7: b | K7: b | L7: b | O7: r | P7: r | Q7: b | R7: b | T7: r | U7: b | V7: b | W7: b | X7: r | Y7: r
A8: 6 | B8: b | C8: b | D8: b | E8: r | F8: b | G8: b | I8: b | J8: b | K8: b | L8: b | O8: b | P8: b | Q8: b | R8: b | T8: b | U8: b | V8: b | W8: b | X8: b | Y8: b
A9: 7 | B9: b | C9: b | D9: b | E9: b | F9: b | G9: b | I9: b | J9: b | K9: b | L9: b | O9: b | P9: b | Q9: b | R9: b | T9: r | U9: r | V9: b | W9: b | X9: r | Y9: b
A10: 8 | B10: r | C10: r | D10: r | E10: r | F10: r | G10: r | I10: r | J10: r | K10: r | L10: b | O10: r | P10: r | Q10: r | R10: r | T10: r | U10: b | V10: r | W10: b | X10: r | Y10: r
A11: 9 | B11: r | C11: r | D11: r | E11: r | F11: r | G11: r | I11: r | J11: r | K11: r | L11: r | O11: r | P11: r | Q11: r | R11: r | T11: r | U11: r | V11: r | W11: b | X11: b | Y11: r
A12: 10 | B12: r | C12: b | D12: b | E12: r | F12: b | G12: r | I12: b | J12: b | K12: b | L12: r | O12: b | P12: b | Q12: r | R12: b | T12: b | U12: r | V12: r | W12: b | X12: b | Y12: b
A17: DS2-E, H | B17: ECG200 | C17: L82 | I17: L97 | O17: L100 | U17: No Simp
A18: Instance | B18: Answers | C18: E1 | D18: E2 | E18: E3 | F18: E4 | G18: E5 | H18: E6 | I18: F1 | J18: F2 | K18: F3 | L18: F4 | M18: F5 | N18: F6 | O18: G1 | P18: G2 | Q18: G3 | R18: G4 | S18: G5 | T18: G6 | U18: H1 | V18: H2 | W18: H3 | X18: H4 | Y18: H5 | Z18: H6
A19: 1 | B19: b | C19: b | D19: b | E19: b | F19: r | H19: b | I19: b | J19: b | K19: b | L19: b | M19: b | O19: b | P19: b | Q19: b | R19: r | S19: b | U19: b | V19: b | W19: b | X19: b
A20: 2 | B20: r | C20: r | D20: r | E20: r | F20: b | H20: r | I20: r | J20: r | K20: r | L20: r | M20: r | O20: b | P20: r | Q20: r | R20: b | S20: r | U20: r | V20: r | W20: r | X20: r
A21: 3 | B21: r | C21: r | D21: r | E21: r | F21: r | H21: r | I21: r | J21: r | K21: r | L21: r | M21: r | O21: b | P21: r | Q21: r | R21: r | S21: r | U21: r | V21: r | W21: r | X21: r
A22: 4 | B22: b | C22: r | D22: b | E22: r | F22: r | H22: r | I22: r | J22: r | K22: r | L22: r | M22: b | O22: b | P22: b | Q22: b | R22: b | S22: b | U22: r | V22: b | W22: b | X22: r
A23: 5 | B23: b | C23: b | D23: b | E23: r | F23: r | H23: b | I23: b | J23: b | K23: b | L23: b | M23: b | O23: r | P23: b | Q23: r | R23: b | S23: b | U23: b | V23: b | W23: b | X23: b
A24: 6 | B24: b | C24: b | D24: b | E24: b | F24: b | H24: b | I24: r | J24: r | K24: r | L24: r | M24: b | O24: r | P24: r | Q24: r | R24: b | S24: r | U24: b | V24: r | W24: r | X24: r
A25: 7 | B25: b | C25: r | D25: r | E25: r | F25: r | H25: r | I25: b | J25: b | K25: b | L25: b | M25: b | O25: b | P25: r | Q25: b | R25: b | S25: b | U25: r | V25: r | W25: b | X25: r
A26: 8 | B26: r | C26: r | D26: r | E26: r | H26: r | I26: r | J26: r | K26: r | L26: r | M26: r | O26: r | P26: r | Q26: r | R26: b | S26: r | U26: r | V26: r | W26: b | X26: r
A27: 9 | B27: r | C27: r | D27: r | E27: r | F27: r | H27: r | I27: b | J27: b | K27: b | L27: b | M27: r | O27: r | P27: r | Q27: r | R27: b | S27: b | U27: b | V27: r | W27: b | X27: r
A28: 10 | B28: r | C28: r | D28: b | E28: r | F28: r | H28: b | I28: r | J28: b | K28: r | L28: b | M28: r | O28: r | P28: r | Q28: r | R28: r | S28: r | U28: r | V28: r | W28: r | X28: r
A36: DS3-I,L | B36: SonyAIBORobotSurface1 | C36: L90 | I36: L96 | O36: L100 | U36: No Simp
A37: Instance | B37: Answers | C37: I1 | D37: I2 | E37: I3 | F37: I4 | G37: I5 | H37: I6 | I37: J1 | J37: J2 | K37: J3 | L37: J4 | M37: J5 | N37: J6 | O37: K1 | P37: K2 | Q37: K3 | R37: K4 | S37: K5 | T37: K6 | U37: L1 | V37: L2 | W37: L3 | X37: L4 | Y37: L5 | Z37: L6
A38: 1 | B38: b | C38: b | D38: b | E38: b | F38: b | I38: b | J38: b | K38: b | L38: r | M38: r | O38: r | P38: b | Q38: b | R38: r | S38: b | U38: b | V38: b | W38: b | X38: b | Z38: b
A39: 2 | B39: r | C39: r | D39: b | E39: b | F39: b | I39: r | J39: r | K39: r | L39: r | M39: r | O39: r | P39: r | Q39: r | R39: b | S39: r | U39: b | V39: b | W39: r | X39: b | Z39: b
A40: 3 | B40: r | C40: r | D40: b | E40: b | F40: r | I40: r | J40: r | K40: b | L40: b | M40: r | O40: b | P40: r | Q40: r | R40: r | S40: r | U40: r | V40: r | W40: r | X40: r | Z40: r
A41: 4 | B41: b | C41: r | D41: b | E41: b | F41: b | I41: b | J41: b | K41: b | L41: b | M41: b | O41: b | P41: b | Q41: b | R41: r | S41: b | U41: b | V41: b | W41: b | X41: b | Z41: b
A42: 5 | B42: b | C42: b | D42: b | E42: b | F42: r | I42: b | J42: b | K42: r | L42: b | M42: b | O42: b | P42: b | Q42: b | R42: r | S42: b | U42: b | V42: b | W42: b | X42: b | Z42: b
A43: 6 | B43: b | C43: b | D43: b | E43: b | F43: b | I43: b | J43: b | K43: r | L43: b | M43: r | O43: b | P43: r | Q43: b | R43: b | S43: r | U43: r | V43: r | W43: r | X43: b | Z43: r
A44: 7 | B44: b | C44: b | D44: b | E44: b | F44: b | I44: r | J44: b | K44: b | L44: b | M44: b | O44: b | P44: b | Q44: b | R44: b | S44: b | U44: b | V44: b | W44: b | X44: b | Z44: r
A45: 8 | B45: r | C45: b | D45: b | E45: r | F45: b | I45: b | J45: b | K45: r | L45: b | M45: b | O45: b | P45: r | Q45: r | R45: r | S45: b | U45: r | W45: r | X45: r | Z45: r
A46: 9 | B46: r | C46: b | D46: r | E46: r | F46: r | I46: r | J46: r | K46: b | L46: b | M46: r | O46: r | P46: r | Q46: r | R46: b | S46: b | U46: r | V46: r | W46: r | X46: r | Z46: b
A47: 10 | B47: r | C47: r | D47: b | E47: b | F47: r | I47: r | J47: r | K47: r | L47: r | M47: r | O47: r | P47: r | Q47: r | R47: r | S47: r | U47: r | V47: r | W47: r | X47: r | Z47: r
A52: DS4-M,P | B52: UMD | C52: L95 | I52: L99 | O52: L100 | U52: No Simp
A53: Instance | B53: Answers | C53: M1 | D53: M2 | E53: M3 | F53: M4 | G53: M5 | H53: M6 | I53: N1 | J53: N2 | K53: N3 | L53: N4 | M53: N5 | N53: N6 | O53: O1 | P53: O2 | Q53: O3 | R53: O4 | S53: O5 | T53: O6 | U53: P1 | V53: P2 | W53: P3 | X53: P4 | Y53: P5 | Z53: P6
A54: 1 | B54: g | C54: g | D54: g | E54: g | F54: g | G54: g | I54: g | J54: g | K54: g | L54: g | N54: g | O54: g | P54: g | Q54: g | R54: g | U54: g | V54: g | W54: g | X54: g | Y54: g
A55: 2 | B55: r | C55: r | D55: r | E55: r | F55: r | G55: r | I55: r | J55: r | K55: r | L55: r | N55: r | O55: r | P55: r | Q55: r | R55: r | U55: r | V55: r | W55: r | X55: r | Y55: r
...

Sheet Sheet2
A1: DS1-A,D | B1: Chinatown | C1: L72 | I1: L92 | O1: L100 | U1: No Simp
A2: Instance | B2: Answers | C2: A1 | D2: A2 | E2: A3 | F2: A4 | G2: A5 | H2: A6 | I2: B1 | J2: B2 | K2: B3 | L2: B4 | M2: B5 | N2: B6 | O2: C1 | P2: C2 | Q2: C3 | R2: C4 | S2: C5 | T2: C6 | U2: D1 | V2: D2 | W2: D3 | X2: D4 | Y2: D5 | Z2: D6
B3: =Sheet1!B3 -> b | C3: =if($B3=Sheet1!C3,1,0) -> 1 | D3: =if($B3=Sheet1!D3,1,0) -> 1 | E3: =if($B3=Sheet1!E3,1,0) -> 1 | F3: =if($B3=Sheet1!F3,1,0) -> 1 | G3: =if($B3=Sheet1!G3,1,0) -> 1 | H3: =if($B3=Sheet1!H3,1,0) -> 0 | I3: =if($B3=Sheet1!I3,1,0) -> 1 | J3: =if($B3=Sheet1!J3,1,0) -> 1 | ... Z3: =if($B3=Sheet1!Z3,1,0) -> 0
B4: =Sheet1!B4 -> r | C4: =if(B4=Sheet1!C4,1,0) -> 0 | D4: =if($B4=Sheet1!D4,1,0) -> 1 | E4: =if($B4=Sheet1!E4,1,0) -> 0 | F4: =if($B4=Sheet1!F4,1,0) -> 0 | G4: =if($B4=Sheet1!G4,1,0) -> 0 | H4: =if($B4=Sheet1!H4,1,0) -> 0 | I4: =if($B4=Sheet1!I4,1,0) -> 1 | J4: =if($B4=Sheet1!J4,1,0) -> 0 | K4: =if($B4=Sheet1!K4,1,0) -> 0 | ... Z4: =if($B4=Sheet1!Z4,1,0) -> 0
B5: =Sheet1!B5 -> r | C5: =if(B5=Sheet1!C5,1,0) -> 1 | D5: =if($B5=Sheet1!D5,1,0) -> 1 | E5: =if($B5=Sheet1!E5,1,0) -> 1 | F5: =if($B5=Sheet1!F5,1,0) -> 1 | G5: =if($B5=Sheet1!G5,1,0) -> 1 | H5: =if($B5=Sheet1!H5,1,0) -> 0 | I5: =if($B5=Sheet1!I5,1,0) -> 1 | J5: =if($B5=Sheet1!J5,1,0) -> 1 | K5: =if($B5=Sheet1!K5,1,0) -> 1 | ... Z5: =if($B5=Sheet1!Z5,1,0) -> 0
B6: =Sheet1!B6 -> b | C6: =if(B6=Sheet1!C6,1,0) -> 1 | D6: =if($B6=Sheet1!D6,1,0) -> 1 | E6: =if($B6=Sheet1!E6,1,0) -> 1 | F6: =if($B6=Sheet1!F6,1,0) -> 1 | G6: =if($B6=Sheet1!G6,1,0) -> 1 | H6: =if($B6=Sheet1!H6,1,0) -> 0 | I6: =if($B6=Sheet1!I6,1,0) -> 1 | J6: =if($B6=Sheet1!J6,1,0) -> 1 | K6: =if($B6=Sheet1!K6,1,0) -> 1 | ... Z6: =if($B6=Sheet1!Z6,1,0) -> 0
B7: =Sheet1!B7 -> b | C7: =if(B7=Sheet1!C7,1,0) -> 1 | D7: =if($B7=Sheet1!D7,1,0) -> 0 | E7: =if($B7=Sheet1!E7,1,0) -> 0 | F7: =if($B7=Sheet1!F7,1,0) -> 0 | G7: =if($B7=Sheet1!G7,1,0) -> 1 | H7: =if($B7=Sheet1!H7,1,0) -> 0 | I7: =if($B7=Sheet1!I7,1,0) -> 1 | J7: =if($B7=Sheet1!J7,1,0) -> 1 | K7: =if($B7=Sheet1!K7,1,0) -> 1 | ... Z7: =if($B7=Sheet1!Z7,1,0) -> 0
B8: =Sheet1!B8 -> b | C8: =if(B8=Sheet1!C8,1,0) -> 1 | D8: =if($B8=Sheet1!D8,1,0) -> 1 | E8: =if($B8=Sheet1!E8,1,0) -> 0 | F8: =if($B8=Sheet1!F8,1,0) -> 1 | G8: =if($B8=Sheet1!G8,1,0) -> 1 | H8: =if($B8=Sheet1!H8,1,0) -> 0 | I8: =if($B8=Sheet1!I8,1,0) -> 1 | J8: =if($B8=Sheet1!J8,1,0) -> 1 | K8: =if($B8=Sheet1!K8,1,0) -> 1 | ... Z8: =if($B8=Sheet1!Z8,1,0) -> 0
B9: =Sheet1!B9 -> b | C9: =if(B9=Sheet1!C9,1,0) -> 1 | D9: =if($B9=Sheet1!D9,1,0) -> 1 | E9: =if($B9=Sheet1!E9,1,0) -> 1 | F9: =if($B9=Sheet1!F9,1,0) -> 1 | G9: =if($B9=Sheet1!G9,1,0) -> 1 | H9: =if($B9=Sheet1!H9,1,0) -> 0 | I9: =if($B9=Sheet1!I9,1,0) -> 1 | J9: =if($B9=Sheet1!J9,1,0) -> 1 | K9: =if($B9=Sheet1!K9,1,0) -> 1 | ... Z9: =if($B9=Sheet1!Z9,1,0) -> 0
B10: =Sheet1!B10 -> r | C10: =if(B10=Sheet1!C10,1,0) -> 1 | D10: =if($B10=Sheet1!D10,1,0) -> 1 | E10: =if($B10=Sheet1!E10,1,0) -> 1 | F10: =if($B10=Sheet1!F10,1,0) -> 1 | G10: =if($B10=Sheet1!G10,1,0) -> 1 | H10: =if($B10=Sheet1!H10,1,0) -> 0 | I10: =if($B10=Sheet1!I10,1,0) -> 1 | J10: =if($B10=Sheet1!J10,1,0) -> 1 | K10: =if($B10=Sheet1!K10,1,0) -> 1 | ... Z10: =if($B10=Sheet1!Z10,1,0) -> 0
B11: =Sheet1!B11 -> r | C11: =if(B11=Sheet1!C11,1,0) -> 1 | D11: =if($B11=Sheet1!D11,1,0) -> 1 | E11: =if($B11=Sheet1!E11,1,0) -> 1 | F11: =if($B11=Sheet1!F11,1,0) -> 1 | G11: =if($B11=Sheet1!G11,1,0) -> 1 | H11: =if($B11=Sheet1!H11,1,0) -> 0 | I11: =if($B11=Sheet1!I11,1,0) -> 1 | J11: =if($B11=Sheet1!J11,1,0) -> 1 | K11: =if($B11=Sheet1!K11,1,0) -> 1 | ... Z11: =if($B11=Sheet1!Z11,1,0) -> 0
B12: =Sheet1!B12 -> r | C12: =if(B12=Sheet1!C12,1,0) -> 0 | D12: =if($B12=Sheet1!D12,1,0) -> 0 | E12: =if($B12=Sheet1!E12,1,0) -> 1 | F12: =if($B12=Sheet1!F12,1,0) -> 0 | G12: =if($B12=Sheet1!G12,1,0) -> 1 | H12: =if($B12=Sheet1!H12,1,0) -> 0 | I12: =if($B12=Sheet1!I12,1,0) -> 0 | J12: =if($B12=Sheet1!J12,1,0) -> 0 | K12: =if($B12=Sheet1!K12,1,0) -> 0 | ... Z12: =if($B12=Sheet1!Z12,1,0) -> 0
B13: Acc | C13: =SUM(C3:C12)/10 -> 0.8 | D13: =SUM(D3:D12)/10 -> 0.8 | E13: =SUM(E3:E12)/10 -> 0.7 | F13: =SUM(F3:F12)/10 -> 0.7 | G13: =SUM(G3:G12)/10 -> 0.9 | H13: =SUM(H3:H12)/10 -> 0 | I13: =SUM(I3:I12)/10 -> 0.9 | J13: =SUM(J3:J12)/10 -> 0.8 | ... Z13: =SUM(Z3:Z12)/10 -> 0
A14: Acc per Simp Level | C14: =AVERAGEIF(C13:H13, "<>0", C13:H13) -> 0.78 | I14: =AVERAGEIF(I13:N13, "<>0", I13:N13) -> 0.825 | O14: =AVERAGEIF(O13:T13, "<>0", O13:T13) -> 0.76 | U14: =AVERAGEIF(U13:Z13, "<>0", U13:Z13) -> 0.66
C15: =sum(CORREL(C3:C12,D3:D12),CORREL(C3:C12,E3:E12),CORREL(C3:C12,F3:F12),CORREL(C3:C12,G3:G12))/4 -> 0.50591179 | D15: =sum(CORREL(D3:D12,C3:C12),CORREL(D3:D12,F3:F12),CORREL(D3:D12,G3:G12),CORREL(D3:D12,E3:E12))/4 -> 0.29757846 | E15: =sum(CORREL(E3:E12,F3:F12),CORREL(E3:E12,G3:G12),CORREL(E3:E12,C3:C12),CORREL(E3:E12,D3:D12))/4 -> 0.3673551 | F15: =sum(CORREL(F3:F12,C3:C12),CORREL(F3:F12,D3:D12),CORREL(F3:F12,E3:E12),CORREL(F3:F12,G3:G12))/4 -> 0.64012746 | G15: =sum(CORREL(G3:G12,D3:D12),CORREL(G3:G12,E3:E12),CORREL(G3:G12,F3:F12),CORREL(G3:G12,C3:C12))/4 -> 0.37958754
A17: DS2-E, H | B17: ECG200 | C17: L82 | I17: L97 | O17: L100 | U17: No Simp
A18: Instance | B18: Answers | C18: E1 | D18: E2 | E18: E3 | F18: E4 | G18: E5 | H18: E6 | I18: F1 | J18: F2 | K18: F3 | L18: F4 | M18: F5 | N18: F6 | O18: G1 | P18: G2 | Q18: G3 | R18: G4 | S18: G5 | T18: G6 | U18: H1 | V18: H2 | W18: H3 | X18: H4 | Y18: H5 | Z18: H6
B19: =Sheet1!B19 -> b | C19: =if($B19=Sheet1!C19,1,0) -> 1 | D19: =if($B19=Sheet1!D19,1,0) -> 1 | E19: =if($B19=Sheet1!E19,1,0) -> 1 | F19: =if($B19=Sheet1!F19,1,0) -> 0 | G19: =if($B19=Sheet1!G19,1,0) -> 0 | H19: =if($B19=Sheet1!H19,1,0) -> 1 | I19: =if($B19=Sheet1!I19,1,0) -> 1 | J19: =if($B19=Sheet1!J19,1,0) -> 1 | ... Z19: =if($B19=Sheet1!Z19,1,0) -> 0
B20: =Sheet1!B20 -> r | C20: =if(B20=Sheet1!C20,1,0) -> 1 | D20: =if($B20=Sheet1!D20,1,0) -> 1 | E20: =if($B20=Sheet1!E20,1,0) -> 1 | F20: =if($B20=Sheet1!F20,1,0) -> 0 | G20: =if($B20=Sheet1!G20,1,0) -> 0 | H20: =if($B20=Sheet1!H20,1,0) -> 1 | I20: =if($B20=Sheet1!I20,1,0) -> 1 | J20: =if($B20=Sheet1!J20,1,0) -> 1 | K20: =if($B20=Sheet1!K20,1,0) -> 1 | ... Z20: =if($B20=Sheet1!Z20,1,0) -> 0
B21: =Sheet1!B21 -> r | C21: =if(B21=Sheet1!C21,1,0) -> 1 | D21: =if($B21=Sheet1!D21,1,0) -> 1 | E21: =if($B21=Sheet1!E21,1,0) -> 1 | F21: =if($B21=Sheet1!F21,1,0) -> 1 | G21: =if($B21=Sheet1!G21,1,0) -> 0 | H21: =if($B21=Sheet1!H21,1,0) -> 1 | I21: =if($B21=Sheet1!I21,1,0) -> 1 | J21: =if($B21=Sheet1!J21,1,0) -> 1 | K21: =if($B21=Sheet1!K21,1,0) -> 1 | ... Z21: =if($B21=Sheet1!Z21,1,0) -> 0
B22: =Sheet1!B22 -> b | C22: =if(B22=Sheet1!C22,1,0) -> 0 | D22: =if($B22=Sheet1!D22,1,0) -> 1 | E22: =if($B22=Sheet1!E22,1,0) -> 0 | F22: =if($B22=Sheet1!F22,1,0) -> 0 | G22: =if($B22=Sheet1!G22,1,0) -> 0 | H22: =if($B22=Sheet1!H22,1,0) -> 0 | I22: =if($B22=Sheet1!I22,1,0) -> 0 | J22: =if($B22=Sheet1!J22,1,0) -> 0 | K22: =if($B22=Sheet1!K22,1,0) -> 0 | ... Z22: =if($B22=Sheet1!Z22,1,0) -> 0
B23: =Sheet1!B23 -> b | C23: =if(B23=Sheet1!C23,1,0) -> 1 | D23: =if($B23=Sheet1!D23,1,0) -> 1 | E23: =if($B23=Sheet1!E23,1,0) -> 0 | F23: =if($B23=Sheet1!F23,1,0) -> 0 | G23: =if($B23=Sheet1!G23,1,0) -> 0 | H23: =if($B23=Sheet1!H23,1,0) -> 1 | I23: =if($B23=Sheet1!I23,1,0) -> 1 | J23: =if($B23=Sheet1!J23,1,0) -> 1 | K23: =if($B23=Sheet1!K23,1,0) -> 1 | ... Z23: =if($B23=Sheet1!Z23,1,0) -> 0
B24: =Sheet1!B24 -> b | C24: =if(B24=Sheet1!C24,1,0) -> 1 | D24: =if($B24=Sheet1!D24,1,0) -> 1 | E24: =if($B24=Sheet1!E24,1,0) -> 1 | F24: =if($B24=Sheet1!F24,1,0) -> 1 | G24: =if($B24=Sheet1!G24,1,0) -> 0 | H24: =if($B24=Sheet1!H24,1,0) -> 1 | I24: =if($B24=Sheet1!I24,1,0) -> 0 | J24: =if($B24=Sheet1!J24,1,0) -> 0 | K24: =if($B24=Sheet1!K24,1,0) -> 0 | ... Z24: =if($B24=Sheet1!Z24,1,0) -> 0
B25: =Sheet1!B25 -> b | C25: =if(B25=Sheet1!C25,1,0) -> 0 | D25: =if($B25=Sheet1!D25,1,0) -> 0 | E25: =if($B25=Sheet1!E25,1,0) -> 0 | F25: =if($B25=Sheet1!F25,1,0) -> 0 | G25: =if($B25=Sheet1!G25,1,0) -> 0 | H25: =if($B25=Sheet1!H25,1,0) -> 0 | I25: =if($B25=Sheet1!I25,1,0) -> 1 | J25: =if($B25=Sheet1!J25,1,0) -> 1 | K25: =if($B25=Sheet1!K25,1,0) -> 1 | ... Z25: =if($B25=Sheet1!Z25,1,0) -> 0
B26: =Sheet1!B26 -> r | C26: =if(B26=Sheet1!C26,1,0) -> 1 | D26: =if($B26=Sheet1!D26,1,0) -> 1 | E26: =if($B26=Sheet1!E26,1,0) -> 1 | F26: =if($B26=Sheet1!F26,1,0) -> 0 | G26: =if($B26=Sheet1!G26,1,0) -> 0 | H26: =if($B26=Sheet1!H26,1,0) -> 1 | I26: =if($B26=Sheet1!I26,1,0) -> 1 | J26: =if($B26=Sheet1!J26,1,0) -> 1 | K26: =if($B26=Sheet1!K26,1,0) -> 1 | ... Z26: =if($B26=Sheet1!Z26,1,0) -> 0
B27: =Sheet1!B27 -> r | C27: =if(B27=Sheet1!C27,1,0) -> 1 | D27: =if($B27=Sheet1!D27,1,0) -> 1 | E27: =if($B27=Sheet1!E27,1,0) -> 1 | F27: =if($B27=Sheet1!F27,1,0) -> 1 | G27: =if($B27=Sheet1!G27,1,0) -> 0 | H27: =if($B27=Sheet1!H27,1,0) -> 1 | I27: =if($B27=Sheet1!I27,1,0) -> 0 | J27: =if($B27=Sheet1!J27,1,0) -> 0 | K27: =if($B27=Sheet1!K27,1,0) -> 0 | ... Z27: =if($B27=Sheet1!Z27,1,0) -> 0
B28: =Sheet1!B28 -> r | C28: =if(B28=Sheet1!C28,1,0) -> 1 | D28: =if($B28=Sheet1!D28,1,0) -> 0 | E28: =if($B28=Sheet1!E28,1,0) -> 1 | F28: =if($B28=Sheet1!F28,1,0) -> 1 | G28: =if($B28=Sheet1!G28,1,0) -> 0 | H28: =if($B28=Sheet1!H28,1,0) -> 0 | I28: =if($B28=Sheet1!I28,1,0) -> 1 | J28: =if($B28=Sheet1!J28,1,0) -> 0 | K28: =if($B28=Sheet1!K28,1,0) -> 1 | ... Z28: =if($B28=Sheet1!Z28,1,0) -> 0
B29: Acc | C29: =SUM(C19:C28)/10 -> 0.8 | D29: =SUM(D19:D28)/10 -> 0.8 | E29: =SUM(E19:E28)/10 -> 0.7 | F29: =SUM(F19:F28)/10 -> 0.4 | G29: =SUM(G19:G28)/10 -> 0 | H29: =SUM(H19:H28)/10 -> 0.7 | I29: =SUM(I19:I28)/10 -> 0.7 | J29: =SUM(J19:J28)/10 -> 0.6 | ... Z29: =SUM(Z19:Z28)/10 -> 0
A30: Acc per Simp Level | C30: =AVERAGEIF(C29:H29, "<>0", C29:H29) -> 0.68 | I30: =AVERAGEIF(I29:N29, "<>0", I29:N29) -> 0.72 | O30: =AVERAGEIF(O29:T29, "<>0", O29:T29) -> 0.72 | U30: =AVERAGEIF(U29:Z29, "<>0", U29:Z29) -> 0.725
C31: =sum(CORREL(C19:C28,D19:D28),CORREL(C19:C28,E19:E28),CORREL(C19:C28,F19:F28))/3 -> 0.5156703 | D31: =sum(CORREL(D19:D28,C19:C28),CORREL(D19:D28,F19:F28),CORREL(D19:D28,E19:E28))/3 -> 0.16371861 | E31: =sum(CORREL(E19:E28,F19:F28),CORREL(E19:E28,C19:C28),CORREL(E19:E28,D19:D28))/3 -> 0.505501 | F31: =sum(CORREL(F19:F28,C19:C28),CORREL(F19:F28,D19:D28),CORREL(F19:F28,E19:E28))/3 -> 0.28023623
A36: DS3-I,L | B36: SonyAIBORobotSurface1 | C36: L90 | I36: L96 | O36: L100 | U36: No Simp
A37: Instance | B37: Answers | C37: I1 | D37: I2 | E37: I3 | F37: I4 | G37: I5 | H37: I6 | I37: J1 | J37: J2 | K37: J3 | L37: J4 | M37: J5 | N37: J6 | O37: K1 | P37: K2 | Q37: K3 | R37: K4 | S37: K5 | T37: K6 | U37: L1 | V37: L2 | W37: L3 | X37: L4 | Y37: L5 | Z37: L6
B38: =Sheet1!B38 -> b | C38: =if($B38=Sheet1!C38,1,0) -> 1 | D38: =if($B38=Sheet1!D38,1,0) -> 1 | E38: =if($B38=Sheet1!E38,1,0) -> 1 | F38: =if($B38=Sheet1!F38,1,0) -> 1 | G38: =if($B38=Sheet1!G38,1,0) -> 0 | H38: =if($B38=Sheet1!H38,1,0) -> 0 | I38: =if($B38=Sheet1!I38,1,0) -> 1 | J38: =if($B38=Sheet1!J38,1,0) -> 1 | ... Z38: =if($B38=Sheet1!Z38,1,0) -> 1
B39: =Sheet1!B39 -> r | C39: =if(B39=Sheet1!C39,1,0) -> 1 | D39: =if($B39=Sheet1!D39,1,0) -> 0 | E39: =if($B39=Sheet1!E39,1,0) -> 0 | F39: =if($B39=Sheet1!F39,1,0) -> 0 | G39: =if($B39=Sheet1!G39,1,0) -> 0 | H39: =if($B39=Sheet1!H39,1,0) -> 0 | I39: =if($B39=Sheet1!I39,1,0) -> 1 | J39: =if($B39=Sheet1!J39,1,0) -> 1 | K39: =if($B39=Sheet1!K39,1,0) -> 1 | ... Z39: =if($B39=Sheet1!Z39,1,0) -> 0
B40: =Sheet1!B40 -> r | C40: =if(B40=Sheet1!C40,1,0) -> 1 | D40: =if($B40=Sheet1!D40,1,0) -> 0 | E40: =if($B40=Sheet1!E40,1,0) -> 0 | F40: =if($B40=Sheet1!F40,1,0) -> 1 | G40: =if($B40=Sheet1!G40,1,0) -> 0 | H40: =if($B40=Sheet1!H40,1,0) -> 0 | I40: =if($B40=Sheet1!I40,1,0) -> 1 | J40: =if($B40=Sheet1!J40,1,0) -> 1 | K40: =if($B40=Sheet1!K40,1,0) -> 0 | ... Z40: =if($B40=Sheet1!Z40,1,0) -> 1
B41: =Sheet1!B41 -> b | C41: =if(B41=Sheet1!C41,1,0) -> 0 | D41: =if($B41=Sheet1!D41,1,0) -> 1 | E41: =if($B41=Sheet1!E41,1,0) -> 1 | F41: =if($B41=Sheet1!F41,1,0) -> 1 | G41: =if($B41=Sheet1!G41,1,0) -> 0 | H41: =if($B41=Sheet1!H41,1,0) -> 0 | I41: =if($B41=Sheet1!I41,1,0) -> 1 | J41: =if($B41=Sheet1!J41,1,0) -> 1 | K41: =if($B41=Sheet1!K41,1,0) -> 1 | ... Z41: =if($B41=Sheet1!Z41,1,0) -> 1
B42: =Sheet1!B42 -> b | C42: =if(B42=Sheet1!C42,1,0) -> 1 | D42: =if($B42=Sheet1!D42,1,0) -> 1 | E42: =if($B42=Sheet1!E42,1,0) -> 1 | F42: =if($B42=Sheet1!F42,1,0) -> 0 | G42: =if($B42=Sheet1!G42,1,0) -> 0 | H42: =if($B42=Sheet1!H42,1,0) -> 0 | I42: =if($B42=Sheet1!I42,1,0) -> 1 | J42: =if($B42=Sheet1!J42,1,0) -> 1 | K42: =if($B42=Sheet1!K42,1,0) -> 0 | ... Z42: =if($B42=Sheet1!Z42,1,0) -> 1
B43: =Sheet1!B43 -> b | C43: =if(B43=Sheet1!C43,1,0) -> 1 | D43: =if($B43=Sheet1!D43,1,0) -> 1 | E43: =if($B43=Sheet1!E43,1,0) -> 1 | F43: =if($B43=Sheet1!F43,1,0) -> 1 | G43: =if($B43=Sheet1!G43,1,0) -> 0 | H43: =if($B43=Sheet1!H43,1,0) -> 0 | I43: =if($B43=Sheet1!I43,1,0) -> 1 | J43: =if($B43=Sheet1!J43,1,0) -> 1 | K43: =if($B43=Sheet1!K43,1,0) -> 0 | ... Z43: =if($B43=Sheet1!Z43,1,0) -> 0
B44: =Sheet1!B44 -> b | C44: =if(B44=Sheet1!C44,1,0) -> 1 | D44: =if($B44=Sheet1!D44,1,0) -> 1 | E44: =if($B44=Sheet1!E44,1,0) -> 1 | F44: =if($B44=Sheet1!F44,1,0) -> 1 | G44: =if($B44=Sheet1!G44,1,0) -> 0 | H44: =if($B44=Sheet1!H44,1,0) -> 0 | I44: =if($B44=Sheet1!I44,1,0) -> 0 | J44: =if($B44=Sheet1!J44,1,0) -> 1 | K44: =if($B44=Sheet1!K44,1,0) -> 1 | ... Z44: =if($B44=Sheet1!Z44,1,0) -> 0
B45: =Sheet1!B45 -> r | C45: =if(B45=Sheet1!C45,1,0) -> 0 | D45: =if($B45=Sheet1!D45,1,0) -> 0 | E45: =if($B45=Sheet1!E45,1,0) -> 1 | F45: =if($B45=Sheet1!F45,1,0) -> 0 | G45: =if($B45=Sheet1!G45,1,0) -> 0 | H45: =if($B45=Sheet1!H45,1,0) -> 0 | I45: =if($B45=Sheet1!I45,1,0) -> 0 | J45: =if($B45=Sheet1!J45,1,0) -> 0 | K45: =if($B45=Sheet1!K45,1,0) -> 1 | ... Z45: =if($B45=Sheet1!Z45,1,0) -> 1
...

Sheet Sheet3
A1: Simpl Simulatability | B1: Knee Low | C1: Knee High | D1: L1 | E1: Full | G1: Loyalty | H1: Knee Low | I1: Knee High | J1: L1 | K1: Full
A2: Dataset 1 | B2: 0.78 | C2: 0.825 | D2: 0.76 | E2: 0.66 | G2: Dataset 1 | H2: 0.72 | I2: 0.92 | J2: 1 | K2: 1
A3: Dataset 2 | B3: 0.68 | C3: 0.72 | D3: 0.72 | E3: 0.725 | G3: Dataset 2 | H3: 0.82 | I3: 0.97 | J3: 1 | K3: 1
A4: Dataset 3 | B4: 0.675 | C4: 0.72 | D4: 0.76 | E4: 0.78 | G4: Dataset 3 | H4: 0.9 | I4: 0.96 | J4: 1 | K4: 1
A5: Dataset 4 | B5: 0.98 | C5: 1 | D5: 1 | E5: 0.96 | G5: Dataset 4 | H5: 0.95 | I5: 0.99 | J5: 1 | K5: 1
B8: Dataset 1 | C8: Dataset 2 | D8: Dataset 3 | E8: Dataset 4 | G8: Model Simulatability | H8: Knee Low | I8: Knee High | J8: L1 | K8: Full
A9: Knee Low | B9: 0.78 | C9: 0.68 | D9: 0.675 | E9: 0.98 | G9: Dataset 1 | H9: =H2*B2 -> 0.5616 | I9: =I2*C2 -> 0.759 | J9: =J2*D2 -> 0.76 | K9: =K2*E2 -> 0.66
A10: Knee High | B10: 0.825 | C10: 0.72 | D10: 0.72 | E10: 1 | G10: Dataset 2 | H10: =H3*B3 -> 0.5576 | I10: =I3*C3 -> 0.6984 | J10: =J3*D3 -> 0.72 | K10: =K3*E3 -> 0.725
A11: L1 | B11: 0.76 | C11: 0.72 | D11: 0.76 | E11: 1 | G11: Dataset 3 | H11: =H4*B4 -> 0.6075 | I11: =I4*C4 -> 0.6912 | J11: =J4*D4 -> 0.76 | K11: =K4*E4 -> 0.78
A12: Full | B12: 0.66 | C12: 0.725 | D12: 0.78 | E12: 0.96 | G12: Dataset 4 | H12: =H5*B5 -> 0.931 | I12: =I5*C5 -> 0.99 | J12: =J5*D5 -> 1 | K12: =K5*E5 -> 0.96
